Workbook

Sheet StudentData
A1: StudentID | B1: Name | C1: First Name | D1: Last Name | E1: Age | F1: Gender | G1: Class | H1: Section | I1: Attendance | J1: Assignments Avg | K1: Midterm Score | L1: Improvement | M1: Final Exam Score | N1: Project Score | O1: Participation | P1: Study Hours | Q1: Extracurricular | R1: Parent Education | S1: Socio-Economic | T1: Final Score | U1: Grade | V1: Result | W1: At-Risk | X1: Study Status
A2: S1001 | B2: Diksha Salunke | C2: =LEFT(Table1[[#This Row],[Name]],SEARCH(" ",Table1[[#This Row],[Name]])-1) -> Diksha | D2: =RIGHT(Table1[[#This Row],[Name]],LEN(Table1[[#This Row],[Name]])-SEARCH(" ",Table1[[#This Row],[Name]])) -> Salunke | E2: 17 | F2: Female | G2: 9th | H2: A | I2: 86.7 | J2: 92.2 | K2: 90 | L2: =Table1[[#This Row],[Final Exam Score]]-Table1[[#This Row],[Midterm Score]] -> -0.5 | M2: 89.5 | N2: 94.3 | O2: 10 | P2: 6.8 | Q2: Art | R2: Post Graduate | S2: High | T2: =Table1[[#This Row],[Assignments Avg]]*0.1+Table1[[#This Row],[Midterm Score]]*0.3+Table1[[#This Row],[Final Exam Score]]*0.45+Table1[[#This Row],[Project Score]]*0.1 -> 85.925 | U2: =IF(Table1[[#This Row],[Final Score]]>=80,"A",IF(Table1[[#This Row],[Final Score]]>=70,"B",IF(Table1[[#This Row],[Final Score]]>=60,"C",IF(Table1[[#This Row],[Final Score]]>=50,"D","F")))) -> A | V2: =IF(Table1[[#This Row],[Final Score]]>=40,"Pass","Fail") -> Pass | W2: =IF(OR(Table1[[#This Row],[Attendance]]<75,Table1[[#This Row],[Final Score]]<45),"At-risk","Ok") -> Ok | X2: =IF(Table1[[#This Row],[Study Hours]]<2,"Low Study","Normal") -> Normal
A3: S1002 | B3: Somnath Hake | C3: =LEFT(Table1[[#This Row],[Name]],SEARCH(" ",Table1[[#This Row],[Name]])-1) -> Somnath | D3: =RIGHT(Table1[[#This Row],[Name]],LEN(Table1[[#This Row],[Name]])-SEARCH(" ",Table1[[#This Row],[Name]])) -> Hake | E3: 17 | F3: Male | G3: 9th | H3: B | I3: 80.3 | J3: 92.2 | K3: 94.2 | L3: =Table1[[#This Row],[Final Exam Score]]-Table1[[#This Row],[Midterm Score]] -> -19.1 | M3: 75.1 | N3: 94.3 | O3: 10 | P3: 6.8 | Q3: Coding | R3: Post Graduate | S3: Medium | T3: =Table1[[#This Row],[Assignments Avg]]*0.1+Table1[[#This Row],[Midterm Score]]*0.3+Table1[[#This Row],[Final Exam Score]]*0.45+Table1[[#This Row],[Project Score]]*0.1 -> 80.705 | U3: =IF(Table1[[#This Row],[Final Score]]>=80,"A",IF(Table1[[#This Row],[Final Score]]>=70,"B",IF(Table1[[#This Row],[Final Score]]>=60,"C",IF(Table1[[#This Row],[Final Score]]>=50,"D","F")))) -> A | V3: =IF(Table1[[#This Row],[Final Score]]>=40,"Pass","Fail") -> Pass | W3: =IF(OR(Table1[[#This Row],[Attendance]]<75,Table1[[#This Row],[Final Score]]<45),"At-risk","Ok") -> Ok | X3: =IF(Table1[[#This Row],[Study Hours]]<2,"Low Study","Normal") -> Normal
A4: S1003 | B4: Manish More | C4: =LEFT(Table1[[#This Row],[Name]],SEARCH(" ",Table1[[#This Row],[Name]])-1) -> Manish | D4: =RIGHT(Table1[[#This Row],[Name]],LEN(Table1[[#This Row],[Name]])-SEARCH(" ",Table1[[#This Row],[Name]])) -> More | E4: 16 | F4: male | G4: 10th | H4: A | I4: 66.4 | J4: 83.8 | K4: 36.2 | L4: =Table1[[#This Row],[Final Exam Score]]-Table1[[#This Row],[Midterm Score]] -> 32.7 | M4: 68.9 | N4: 68.1 | O4: 3 | P4: 4.9 | Q4: Music | R4: HSC | S4: Low | T4: =Table1[[#This Row],[Assignments Avg]]*0.1+Table1[[#This Row],[Midterm Score]]*0.3+Table1[[#This Row],[Final Exam Score]]*0.45+Table1[[#This Row],[Project Score]]*0.1 -> 57.055 | U4: =IF(Table1[[#This Row],[Final Score]]>=80,"A",IF(Table1[[#This Row],[Final Score]]>=70,"B",IF(Table1[[#This Row],[Final Score]]>=60,"C",IF(Table1[[#This Row],[Final Score]]>=50,"D","F")))) -> D | V4: =IF(Table1[[#This Row],[Final Score]]>=40,"Pass","Fail") -> Pass | W4: =IF(OR(Table1[[#This Row],[Attendance]]<75,Table1[[#This Row],[Final Score]]<45),"At-risk","Ok") -> At-risk | X4: =IF(Table1[[#This Row],[Study Hours]]<2,"Low Study","Normal") -> Normal
A5: S1004 | B5: Rohan Jadhav | C5: =LEFT(Table1[[#This Row],[Name]],SEARCH(" ",Table1[[#This Row],[Name]])-1) -> Rohan | D5: =RIGHT(Table1[[#This Row],[Name]],LEN(Table1[[#This Row],[Name]])-SEARCH(" ",Table1[[#This Row],[Name]])) -> Jadhav | E5: 15 | F5: Male | G5: 10th | H5: C | I5: 91.8 | J5: 83.8 | K5: 87.4 | L5: =Table1[[#This Row],[Final Exam Score]]-Table1[[#This Row],[Midterm Score]] -> -51.2 | M5: 36.2 | N5: 76.9 | O5: 5 | P5: 1.6 | Q5: Dance | R5: Illiterate | S5: Low | T5: =Table1[[#This Row],[Assignments Avg]]*0.1+Table1[[#This Row],[Midterm Score]]*0.3+Table1[[#This Row],[Final Exam Score]]*0.45+Table1[[#This Row],[Project Score]]*0.1 -> 58.58 | U5: =IF(Table1[[#This Row],[Final Score]]>=80,"A",IF(Table1[[#This Row],[Final Score]]>=70,"B",IF(Table1[[#This Row],[Final Score]]>=60,"C",IF(Table1[[#This Row],[Final Score]]>=50,"D","F")))) -> D | V5: =IF(Table1[[#This Row],[Final Score]]>=40,"Pass","Fail") -> Pass | W5: =IF(OR(Table1[[#This Row],[Attendance]]<75,Table1[[#This Row],[Final Score]]<45),"At-risk","Ok") -> Ok | X5: =IF(Table1[[#This Row],[Study Hours]]<2,"Low Study","Normal") -> Low Study
A6: S1005 | B6: Harsh Kulkarni | C6: =LEFT(Table1[[#This Row],[Name]],SEARCH(" ",Table1[[#This Row],[Name]])-1) -> Harsh | D6: =RIGHT(Table1[[#This Row],[Name]],LEN(Table1[[#This Row],[Name]])-SEARCH(" ",Table1[[#This Row],[Name]])) -> Kulkarni | E6: 15 | F6: Male | G6: 9th | H6: A | I6: 71.3 | J6: 79.9 | K6: 25.2 | L6: =Table1[[#This Row],[Final Exam Score]]-Table1[[#This Row],[Midterm Score]] -> 54.7 | M6: 79.9 | N6: 80.2 | O6: 7 | P6: 2.8 | Q6: Coding | R6: SSC | S6: High | T6: =Table1[[#This Row],[Assignments Avg]]*0.1+Table1[[#This Row],[Midterm Score]]*0.3+Table1[[#This Row],[Final Exam Score]]*0.45+Table1[[#This Row],[Project Score]]*0.1 -> 59.525 | U6: =IF(Table1[[#This Row],[Final Score]]>=80,"A",IF(Table1[[#This Row],[Final Score]]>=70,"B",IF(Table1[[#This Row],[Final Score]]>=60,"C",IF(Table1[[#This Row],[Final Score]]>=50,"D","F")))) -> D | V6: =IF(Table1[[#This Row],[Final Score]]>=40,"Pass","Fail") -> Pass | W6: =IF(OR(Table1[[#This Row],[Attendance]]<75,Table1[[#This Row],[Final Score]]<45),"At-risk","Ok") -> At-risk | X6: =IF(Table1[[#This Row],[Study Hours]]<2,"Low Study","Normal") -> Normal
A7: S1006 | B7: Virat Singh | C7: =LEFT(Table1[[#This Row],[Name]],SEARCH(" ",Table1[[#This Row],[Name]])-1) -> Virat | D7: =RIGHT(Table1[[#This Row],[Name]],LEN(Table1[[#This Row],[Name]])-SEARCH(" ",Table1[[#This Row],[Name]])) -> Singh | E7: 16 | F7: Male | G7: 9th | H7: B | I7: 76.5 | J7: 68.9 | K7: 76.6 | L7: =Table1[[#This Row],[Final Exam Score]]-Table1[[#This Row],[Midterm Score]] -> -8.4 | M7: 68.2 | N7: 87.8 | O7: 9 | P7: 1.7 | Q7: Sports | R7: Post Graduate | S7: Medium | T7: =Table1[[#This Row],[Assignments Avg]]*0.1+Table1[[#This Row],[Midterm Score]]*0.3+Table1[[#This Row],[Final Exam Score]]*0.45+Table1[[#This Row],[Project Score]]*0.1 -> 69.34 | U7: =IF(Table1[[#This Row],[Final Score]]>=80,"A",IF(Table1[[#This Row],[Final Score]]>=70,"B",IF(Table1[[#This Row],[Final Score]]>=60,"C",IF(Table1[[#This Row],[Final Score]]>=50,"D","F")))) -> C | V7: =IF(Table1[[#This Row],[Final Score]]>=40,"Pass","Fail") -> Pass | W7: =IF(OR(Table1[[#This Row],[Attendance]]<75,Table1[[#This Row],[Final Score]]<45),"At-risk","Ok") -> Ok | X7: =IF(Table1[[#This Row],[Study Hours]]<2,"Low Study","Normal") -> Low Study | Y7: Row Labels | Z7: Average of Final Score
A8: S1007 | B8: Abhishek Joshi | C8: =LEFT(Table1[[#This Row],[Name]],SEARCH(" ",Table1[[#This Row],[Name]])-1) -> Abhishek | D8: =RIGHT(Table1[[#This Row],[Name]],LEN(Table1[[#This Row],[Name]])-SEARCH(" ",Table1[[#This Row],[Name]])) -> Joshi | E8: 17 | F8: Male | G8: 10th | H8: C | I8: 92 | J8: 68.2 | K8: 70 | L8: =Table1[[#This Row],[Final Exam Score]]-Table1[[#This Row],[Midterm Score]] -> -23 | M8: 47 | N8: 80.2 | O8: 6 | P8: 4.9 | Q8: Sports | R8: SSC | S8: High | T8: =Table1[[#This Row],[Assignments Avg]]*0.1+Table1[[#This Row],[Midterm Score]]*0.3+Table1[[#This Row],[Final Exam Score]]*0.45+Table1[[#This Row],[Project Score]]*0.1 -> 56.99 | U8: =IF(Table1[[#This Row],[Final Score]]>=80,"A",IF(Table1[[#This Row],[Final Score]]>=70,"B",IF(Table1[[#This Row],[Final Score]]>=60,"C",IF(Table1[[#This Row],[Final Score]]>=50,"D","F")))) -> D | V8: =IF(Table1[[#This Row],[Final Score]]>=40,"Pass","Fail") -> Pass | W8: =IF(OR(Table1[[#This Row],[Attendance]]<75,Table1[[#This Row],[Final Score]]<45),"At-risk","Ok") -> Ok | X8: =IF(Table1[[#This Row],[Study Hours]]<2,"Low Study","Normal") -> Normal | Y8: 10th | Z8: 65.205833
A9: S1008 | B9: Sneha More | C9: =LEFT(Table1[[#This Row],[Name]],SEARCH(" ",Table1[[#This Row],[Name]])-1) -> Sneha | D9: =RIGHT(Table1[[#This Row],[Name]],LEN(Table1[[#This Row],[Name]])-SEARCH(" ",Table1[[#This Row],[Name]])) -> More | E9: 17 | F9: Female | G9: 10th | H9: A | I9: 67.6 | J9: 75.1 | K9: 45.8 | L9: =Table1[[#This Row],[Final Exam Score]]-Table1[[#This Row],[Midterm Score]] -> 23.1 | M9: 68.9 | N9: 47.8 | O9: 4 | P9: 2.9 | Q9: Art | R9: SSC | S9: Medium | T9: =Table1[[#This Row],[Assignments Avg]]*0.1+Table1[[#This Row],[Midterm Score]]*0.3+Table1[[#This Row],[Final Exam Score]]*0.45+Table1[[#This Row],[Project Score]]*0.1 -> 57.035 | U9: =IF(Table1[[#This Row],[Final Score]]>=80,"A",IF(Table1[[#This Row],[Final Score]]>=70,"B",IF(Table1[[#This Row],[Final Score]]>=60,"C",IF(Table1[[#This Row],[Final Score]]>=50,"D","F")))) -> D | V9: =IF(Table1[[#This Row],[Final Score]]>=40,"Pass","Fail") -> Pass | W9: =IF(OR(Table1[[#This Row],[Attendance]]<75,Table1[[#This Row],[Final Score]]<45),"At-risk","Ok") -> At-risk | X9: =IF(Table1[[#This Row],[Study Hours]]<2,"Low Study","Normal") -> Normal | Y9: 9th | Z9: 66.813462
A10: S1009 | B10: Neha Deshmukh | C10: =LEFT(Table1[[#This Row],[Name]],SEARCH(" ",Table1[[#This Row],[Name]])-1) -> Neha | D10: =RIGHT(Table1[[#This Row],[Name]],LEN(Table1[[#This Row],[Name]])-SEARCH(" ",Table1[[#This Row],[Name]])) -> Deshmukh | E10: 17 | F10: Female | G10: 9th | H10: B | I10: 68.9 | J10: 66.4 | K10: 51.6 | L10: =Table1[[#This Row],[Final Exam Score]]-Table1[[#This Row],[Midterm Score]] -> 37.9 | M10: 89.5 | N10: 51.2 | O10: 5 | P10: 4.9 | Q10: Coding | R10: HSC | S10: Low | T10: =Table1[[#This Row],[Assignments Avg]]*0.1+Table1[[#This Row],[Midterm Score]]*0.3+Table1[[#This Row],[Final Exam Score]]*0.45+Table1[[#This Row],[Project Score]]*0.1 -> 67.515 | U10: =IF(Table1[[#This Row],[Final Score]]>=80,"A",IF(Table1[[#This Row],[Final Score]]>=70,"B",IF(Table1[[#This Row],[Final Score]]>=60,"C",IF(Table1[[#This Row],[Final Score]]>=50,"D","F")))) -> C | V10: =IF(Table1[[#This Row],[Final Score]]>=40,"Pass","Fail") -> Pass | W10: =IF(OR(Table1[[#This Row],[Attendance]]<75,Table1[[#This Row],[Final Score]]<45),"At-risk","Ok") -> At-risk | X10: =IF(Table1[[#This Row],[Study Hours]]<2,"Low Study","Normal") -> Normal | Y10: Grand Total | Z10: 66.0418
A11: S1010 | B11: Aditya Thakur | C11: =LEFT(Table1[[#This Row],[Name]],SEARCH(" ",Table1[[#This Row],[Name]])-1) -> Aditya | D11: =RIGHT(Table1[[#This Row],[Name]],LEN(Table1[[#This Row],[Name]])-SEARCH(" ",Table1[[#This Row],[Name]])) -> Thakur | E11: 16 | F11: male | G11: 9th | H11: A | I11: 75.4 | J11: 89.5 | K11: 76.5 | L11: =Table1[[#This Row],[Final Exam Score]]-Table1[[#This Row],[Midterm Score]] -> 3.4 | M11: 79.9 | N11: 91.2 | O11: 1 | P11: 4.9 | Q11: Music | R11: Graduate | S11: High | T11: =Table1[[#This Row],[Assignments Avg]]*0.1+Table1[[#This Row],[Midterm Score]]*0.3+Table1[[#This Row],[Final Exam Score]]*0.45+Table1[[#This Row],[Project Score]]*0.1 -> 76.975 | U11: =IF(Table1[[#This Row],[Final Score]]>=80,"A",IF(Table1[[#This Row],[Final Score]]>=70,"B",IF(Table1[[#This Row],[Final Score]]>=60,"C",IF(Table1[[#This Row],[Final Score]]>=50,"D","F")))) -> B | V11: =IF(Table1[[#This Row],[Final Score]]>=40,"Pass","Fail") -> Pass | W11: =IF(OR(Table1[[#This Row],[Attendance]]<75,Table1[[#This Row],[Final Score]]<45),"At-risk","Ok") -> Ok | X11: =IF(Table1[[#This Row],[Study Hours]]<2,"Low Study","Normal") -> Normal
A12: S1011 | B12: Siddharth Gaikwad | C12: =LEFT(Table1[[#This Row],[Name]],SEARCH(" ",Table1[[#This Row],[Name]])-1) -> Siddharth | D12: =RIGHT(Table1[[#This Row],[Name]],LEN(Table1[[#This Row],[Name]])-SEARCH(" ",Table1[[#This Row],[Name]])) -> Gaikwad | E12: 15 | F12: Male | G12: 10th | H12: C | I12: 65.7 | J12: 47 | K12: 36.2 | L12: =Table1[[#This Row],[Final Exam Score]]-Table1[[#This Row],[Midterm Score]] -> -11 | M12: 25.2 | N12: 50.6 | O12: 7 | P12: 3.7 | Q12: Dance | R12: Post Graduate | S12: Medium | T12: =Table1[[#This Row],[Assignments Avg]]*0.1+Table1[[#This Row],[Midterm Score]]*0.3+Table1[[#This Row],[Final Exam Score]]*0.45+Table1[[#This Row],[Project Score]]*0.1 -> 31.96 | U12: =IF(Table1[[#This Row],[Final Score]]>=80,"A",IF(Table1[[#This Row],[Final Score]]>=70,"B",IF(Table1[[#This Row],[Final Score]]>=60,"C",IF(Table1[[#This Row],[Final Score]]>=50,"D","F")))) -> F | V12: =IF(Table1[[#This Row],[Final Score]]>=40,"Pass","Fail") -> Fail | W12: =IF(OR(Table1[[#This Row],[Attendance]]<75,Table1[[#This Row],[Final Score]]<45),"At-risk","Ok") -> At-risk | X12: =IF(Table1[[#This Row],[Study Hours]]<2,"Low Study","Normal") -> Normal | Y12: Count of Name | Z12: Column Labels
A13: S1012 | B13: Ankit Sharma | C13: =LEFT(Table1[[#This Row],[Name]],SEARCH(" ",Table1[[#This Row],[Name]])-1) -> Ankit | D13: =RIGHT(Table1[[#This Row],[Name]],LEN(Table1[[#This Row],[Name]])-SEARCH(" ",Table1[[#This Row],[Name]])) -> Sharma | E13: 17 | F13: Male | G13: 10th | H13: A | I13: 83.8 | J13: 66.4 | K13: 67.3 | L13: =Table1[[#This Row],[Final Exam Score]]-Table1[[#This Row],[Midterm Score]] -> -6.8 | M13: 60.5 | N13: 68.1 | O13: 3 | P13: 2.7 | Q13: Coding | R13: Illiterate | S13: Low | T13: =Table1[[#This Row],[Assignments Avg]]*0.1+Table1[[#This Row],[Midterm Score]]*0.3+Table1[[#This Row],[Final Exam Score]]*0.45+Table1[[#This Row],[Project Score]]*0.1 -> 60.865 | U13: =IF(Table1[[#This Row],[Final Score]]>=80,"A",IF(Table1[[#This Row],[Final Score]]>=70,"B",IF(Table1[[#This Row],[Final Score]]>=60,"C",IF(Table1[[#This Row],[Final Score]]>=50,"D","F")))) -> C | V13: =IF(Table1[[#This Row],[Final Score]]>=40,"Pass","Fail") -> Pass | W13: =IF(OR(Table1[[#This Row],[Attendance]]<75,Table1[[#This Row],[Final Score]]<45),"At-risk","Ok") -> Ok | X13: =IF(Table1[[#This Row],[Study Hours]]<2,"Low Study","Normal") -> Normal | Y13: Row Labels | Z13: Fail | AA13: Pass | AB13: Grand Total
A14: S1013 | B14: Sanjana Gaikwad | C14: =LEFT(Table1[[#This Row],[Name]],SEARCH(" ",Table1[[#This Row],[Name]])-1) -> Sanjana | D14: =RIGHT(Table1[[#This Row],[Name]],LEN(Table1[[#This Row],[Name]])-SEARCH(" ",Table1[[#This Row],[Name]])) -> Gaikwad | E14: 16 | F14: Female | G14: 9th | H14: B | I14: 75.1 | J14: 36.5 | K14: 51.6 | L14: =Table1[[#This Row],[Final Exam Score]]-Table1[[#This Row],[Midterm Score]] -> 24.9 | M14: 76.5 | N14: 91.2 | O14: 3 | P14: 7.5 | Q14: Sports | R14: Post Graduate | S14: Low | T14: =Table1[[#This Row],[Assignments Avg]]*0.1+Table1[[#This Row],[Midterm Score]]*0.3+Table1[[#This Row],[Final Exam Score]]*0.45+Table1[[#This Row],[Project Score]]*0.1 -> 62.675 | U14: =IF(Table1[[#This Row],[Final Score]]>=80,"A",IF(Table1[[#This Row],[Final Score]]>=70,"B",IF(Table1[[#This Row],[Final Score]]>=60,"C",IF(Table1[[#This Row],[Final Score]]>=50,"D","F")))) -> C | V14: =IF(Table1[[#This Row],[Final Score]]>=40,"Pass","Fail") -> Pass | W14: =IF(OR(Table1[[#This Row],[Attendance]]<75,Table1[[#This Row],[Final Score]]<45),"At-risk","Ok") -> Ok | X14: =IF(Table1[[#This Row],[Study Hours]]<2,"Low Study","Normal") -> Normal | Y14: A | AA14: 22 | AB14: 22
A15: S1014 | B15: Aryan Pawar | C15: =LEFT(Table1[[#This Row],[Name]],SEARCH(" ",Table1[[#This Row],[Name]])-1) -> Aryan | D15: =RIGHT(Table1[[#This Row],[Name]],LEN(Table1[[#This Row],[Name]])-SEARCH(" ",Table1[[#This Row],[Name]])) -> Pawar | E15: 15 | F15: Male | G15: 9th | H15: C | I15: 67 | J15: 50.7 | K15: 33.9 | L15: =Table1[[#This Row],[Final Exam Score]]-Table1[[#This Row],[Midterm Score]] -> 34.3 | M15: 68.2 | N15: 77.9 | O15: 5 | P15: 4.9 | Q15: Sports | R15: Post Graduate | S15: High | T15: =Table1[[#This Row],[Assignments Avg]]*0.1+Table1[[#This Row],[Midterm Score]]*0.3+Table1[[#This Row],[Final Exam Score]]*0.45+Table1[[#This Row],[Project Score]]*0.1 -> 53.72 | U15: =IF(Table1[[#This Row],[Final Score]]>=80,"A",IF(Table1[[#This Row],[Final Score]]>=70,"B",IF(Table1[[#This Row],[Final Score]]>=60,"C",IF(Table1[[#This Row],[Final Score]]>=50,"D","F")))) -> D | V15: =IF(Table1[[#This Row],[Final Score]]>=40,"Pass","Fail") -> Pass | W15: =IF(OR(Table1[[#This Row],[Attendance]]<75,Table1[[#This Row],[Final Score]]<45),"At-risk","Ok") -> At-risk | X15: =IF(Table1[[#This Row],[Study Hours]]<2,"Low Study","Normal") -> Normal | Y15: B | AA15: 14 | AB15: 14
A16: S1015 | B16: Sneha Kadam | C16: =LEFT(Table1[[#This Row],[Name]],SEARCH(" ",Table1[[#This Row],[Name]])-1) -> Sneha | D16: =RIGHT(Table1[[#This Row],[Name]],LEN(Table1[[#This Row],[Name]])-SEARCH(" ",Table1[[#This Row],[Name]])) -> Kadam | E16: 16 | F16: Female | G16: 10th | H16: A | I16: 92.2 | J16: 76.5 | K16: 74.4 | L16: =Table1[[#This Row],[Final Exam Score]]-Table1[[#This Row],[Midterm Score]] -> 12.3 | M16: 86.7 | N16: 68.1 | O16: 7 | P16: 2.6 | Q16: None | R16: HSC | S16: Medium | T16: =Table1[[#This Row],[Assignments Avg]]*0.1+Table1[[#This Row],[Midterm Score]]*0.3+Table1[[#This Row],[Final Exam Score]]*0.45+Table1[[#This Row],[Project Score]]*0.1 -> 75.795 | U16: =IF(Table1[[#This Row],[Final Score]]>=80,"A",IF(Table1[[#This Row],[Final Score]]>=70,"B",IF(Table1[[#This Row],[Final Score]]>=60,"C",IF(Table1[[#This Row],[Final Score]]>=50,"D","F")))) -> B | V16: =IF(Table1[[#This Row],[Final Score]]>=40,"Pass","Fail") -> Pass | W16: =IF(OR(Table1[[#This Row],[Attendance]]<75,Table1[[#This Row],[Final Score]]<45),"At-risk","Ok") -> Ok | X16: =IF(Table1[[#This Row],[Study Hours]]<2,"Low Study","Normal") -> Normal | Y16: C | Z16: 1 | AA16: 13 | AB16: 14
A17: S1016 | B17: Manish Rane | C17: =LEFT(Table1[[#This Row],[Name]],SEARCH(" ",Table1[[#This Row],[Name]])-1) -> Manish | D17: =RIGHT(Table1[[#This Row],[Name]],LEN(Table1[[#This Row],[Name]])-SEARCH(" ",Table1[[#This Row],[Name]])) -> Rane | E17: 16 | F17: Male | G17: 10th | H17: B | I17: 79.9 | J17: 68.9 | K17: 85 | L17: =Table1[[#This Row],[Final Exam Score]]-Table1[[#This Row],[Midterm Score]] -> 4.5 | M17: 89.5 | N17: 82.3 | O17: 9 | P17: 1.5 | Q17: Coding | R17: Illiterate | S17: High | T17: =Table1[[#This Row],[Assignments Avg]]*0.1+Table1[[#This Row],[Midterm Score]]*0.3+Table1[[#This Row],[Final Exam Score]]*0.45+Table1[[#This Row],[Project Score]]*0.1 -> 80.895 | U17: =IF(Table1[[#This Row],[Final Score]]>=80,"A",IF(Table1[[#This Row],[Final Score]]>=70,"B",IF(Table1[[#This Row],[Final Score]]>=60,"C",IF(Table1[[#This Row],[Final Score]]>=50,"D","F")))) -> A | V17: =IF(Table1[[#This Row],[Final Score]]>=40,"Pass","Fail") -> Pass | W17: =IF(OR(Table1[[#This Row],[Attendance]]<75,Table1[[#This Row],[Final Score]]<45),"At-risk","Ok") -> Ok | X17: =IF(Table1[[#This Row],[Study Hours]]<2,"Low Study","Normal") -> Low Study | Y17: Grand Total | Z17: 1 | AA17: 49 | AB17: 50
A18: S1017 | B18: Kunal Shinde | C18: =LEFT(Table1[[#This Row],[Name]],SEARCH(" ",Table1[[#This Row],[Name]])-1) -> Kunal | D18: =RIGHT(Table1[[#This Row],[Name]],LEN(Table1[[#This Row],[Name]])-SEARCH(" ",Table1[[#This Row],[Name]])) -> Shinde | E18: 17 | F18: male | G18: 9th | H18: A | I18: 95.5 | J18: 44.5 | K18: 45.8 | L18: =Table1[[#This Row],[Final Exam Score]]-Table1[[#This Row],[Midterm Score]] -> 40.9 | M18: 86.7 | N18: 50.6 | O18: 6 | P18: 4.9 | Q18: Music | R18: SSC | S18: Medium | T18: =Table1[[#This Row],[Assignments Avg]]*0.1+Table1[[#This Row],[Midterm Score]]*0.3+Table1[[#This Row],[Final Exam Score]]*0.45+Table1[[#This Row],[Project Score]]*0.1 -> 62.265 | U18: =IF(Table1[[#This Row],[Final Score]]>=80,"A",IF(Table1[[#This Row],[Final Score]]>=70,"B",IF(Table1[[#This Row],[Final Score]]>=60,"C",IF(Table1[[#This Row],[Final Score]]>=50,"D","F")))) -> C | V18: =IF(Table1[[#This Row],[Final Score]]>=40,"Pass","Fail") -> Pass | W18: =IF(OR(Table1[[#This Row],[Attendance]]<75,Table1[[#This Row],[Final Score]]<45),"At-risk","Ok") -> Ok | X18: =IF(Table1[[#This Row],[Study Hours]]<2,"Low Study","Normal") -> Normal
A19: S1018 | B19: Kavya More | C19: =LEFT(Table1[[#This Row],[Name]],SEARCH(" ",Table1[[#This Row],[Name]])-1) -> Kavya | D19: =RIGHT(Table1[[#This Row],[Name]],LEN(Table1[[#This Row],[Name]])-SEARCH(" ",Table1[[#This Row],[Name]])) -> More | E19: 15 | F19: Female | G19: 9th | H19: C | I19: 94.9 | J19: 25.2 | K19: 76.5 | L19: =Table1[[#This Row],[Final Exam Score]]-Table1[[#This Row],[Midterm Score]] -> 13 | M19: 89.5 | N19: 76.9 | O19: 4 | P19: 3 | Q19: Dance | R19: Post Graduate | S19: Low | T19: =Table1[[#This Row],[Assignments Avg]]*0.1+Table1[[#This Row],[Midterm Score]]*0.3+Table1[[#This Row],[Final Exam Score]]*0.45+Table1[[#This Row],[Project Score]]*0.1 -> 73.435 | U19: =IF(Table1[[#This Row],[Final Score]]>=80,"A",IF(Table1[[#This Row],[Final Score]]>=70,"B",IF(Table1[[#This Row],[Final Score]]>=60,"C",IF(Table1[[#This Row],[Final Score]]>=50,"D","F")))) -> B | V19: =IF(Table1[[#This Row],[Final Score]]>=40,"Pass","Fail") -> Pass | W19: =IF(OR(Table1[[#This Row],[Attendance]]<75,Table1[[#This Row],[Final Score]]<45),"At-risk","Ok") -> Ok | X19: =IF(Table1[[#This Row],[Study Hours]]<2,"Low Study","Normal") -> Normal | Y19: Row Labels | Z19: Average of Attendance
A20: S1019 | B20: Abhishek Sharma | C20: =LEFT(Table1[[#This Row],[Name]],SEARCH(" ",Table1[[#This Row],[Name]])-1) -> Abhishek | D20: =RIGHT(Table1[[#This Row],[Name]],LEN(Table1[[#This Row],[Name]])-SEARCH(" ",Table1[[#This Row],[Name]])) -> Sharma | E20: 17 | F20: Male | G20: 10th | H20: A | I20: 61.8 | J20: 51.3 | K20: 25.2 | L20: =Table1[[#This Row],[Final Exam Score]]-Table1[[#This Row],[Midterm Score]] -> 67 | M20: 92.2 | N20: 61.5 | O20: 2 | P20: 5.3 | Q20: Coding | R20: SSC | S20: High | T20: =Table1[[#This Row],[Assignments Avg]]*0.1+Table1[[#This Row],[Midterm Score]]*0.3+Table1[[#This Row],[Final Exam Score]]*0.45+Table1[[#This Row],[Project Score]]*0.1 -> 60.33 | U20: =IF(Table1[[#This Row],[Final Score]]>=80,"A",IF(Table1[[#This Row],[Final Score]]>=70,"B",IF(Table1[[#This Row],[Final Score]]>=60,"C",IF(Table1[[#This Row],[Final Score]]>=50,"D","F")))) -> C | V20: =IF(Table1[[#This Row],[Final Score]]>=40,"Pass","Fail") -> Pass | W20: =IF(OR(Table1[[#This Row],[Attendance]]<75,Table1[[#This Row],[Final Score]]<45),"At-risk","Ok") -> At-risk | X20: =IF(Table1[[#This Row],[Study Hours]]<2,"Low Study","Normal") -> Normal | Y20: Female | Z20: 74.66
A21: S1020 | B21: Sanjana Deshmukh | C21: =LEFT(Table1[[#This Row],[Name]],SEARCH(" ",Table1[[#This Row],[Name]])-1) -> Sanjana | D21: =RIGHT(Table1[[#This Row],[Name]],LEN(Table1[[#This Row],[Name]])-SEARCH(" ",Table1[[#This Row],[Name]])) -> Deshmukh | E21: 16 | F21: Female | G21: 10th | H21: B | I21: 85 | J21: 86.7 | K21: 33.9 | L21: =Table1[[#This Row],[Final Exam Score]]-Table1[[#This Row],[Midterm Score]] -> 46 | M21: 79.9 | N21: 91.2 | O21: 5 | P21: 1.6 | Q21: Sports | R21: SSC | S21: Medium | T21: =Table1[[#This Row],[Assignments Avg]]*0.1+Table1[[#This Row],[Midterm Score]]*0.3+Table1[[#This Row],[Final Exam Score]]*0.45+Table1[[#This Row],[Project Score]]*0.1 -> 63.915 | U21: =IF(Table1[[#This Row],[Final Score]]>=80,"A",IF(Table1[[#This Row],[Final Score]]>=70,"B",IF(Table1[[#This Row],[Final Score]]>=60,"C",IF(Table1[[#This Row],[Final Score]]>=50,"D","F")))) -> C | V21: =IF(Table1[[#This Row],[Final Score]]>=40,"Pass","Fail") -> Pass | W21: =IF(OR(Table1[[#This Row],[Attendance]]<75,Table1[[#This Row],[Final Score]]<45),"At-risk","Ok") -> Ok | X21: =IF(Table1[[#This Row],[Study Hours]]<2,"Low Study","Normal") -> Low Study | Y21: Male | Z21: 69.076667
A22: S1021 | B22: Yash Sharma | C22: =LEFT(Table1[[#This Row],[Name]],SEARCH(" ",Table1[[#This Row],[Name]])-1) -> Yash | D22: =RIGHT(Table1[[#This Row],[Name]],LEN(Table1[[#This Row],[Name]])-SEARCH(" ",Table1[[#This Row],[Name]])) -> Sharma | E22: 15 | F22: Male | G22: 9th | H22: C | I22: 51.3 | J22: 68.2 | K22: 90 | L22: =Table1[[#This Row],[Final Exam Score]]-Table1[[#This Row],[Midterm Score]] -> 5.5 | M22: 95.5 | N22: 44.5 | O22: 6 | P22: 1.4 | Q22: Sports | R22: HSC | S22: Low | T22: =Table1[[#This Row],[Assignments Avg]]*0.1+Table1[[#This Row],[Midterm Score]]*0.3+Table1[[#This Row],[Final Exam Score]]*0.45+Table1[[#This Row],[Project Score]]*0.1 -> 81.245 | U22: =IF(Table1[[#This Row],[Final Score]]>=80,"A",IF(Table1[[#This Row],[Final Score]]>=70,"B",IF(Table1[[#This Row],[Final Score]]>=60,"C",IF(Table1[[#This Row],[Final Score]]>=50,"D","F")))) -> A | V22: =IF(Table1[[#This Row],[Final Score]]>=40,"Pass","Fail") -> Pass | W22: =IF(OR(Table1[[#This Row],[Attendance]]<75,Table1[[#This Row],[Final Score]]<45),"At-risk","Ok") -> At-risk | X22: =IF(Table1[[#This Row],[Study Hours]]<2,"Low Study","Normal") -> Low Study | Y22: Grand Total | Z22: 71.31
A23: S1022 | B23: Siddharth Jadhav | C23: =LEFT(Table1[[#This Row],[Name]],SEARCH(" ",Table1[[#This Row],[Name]])-1) -> Siddharth | D23: =RIGHT(Table1[[#This Row],[Name]],LEN(Table1[[#This Row],[Name]])-SEARCH(" ",Table1[[#This Row],[Name]])) -> Jadhav | E23: 15 | F23: Male | G23: 9th | H23: A | I23: 50.7 | J23: 83.8 | K23: 51.6 | L23: =Table1[[#This Row],[Final Exam Score]]-Table1[[#This Row],[Midterm Score]] -> 43.3 | M23: 94.9 | N23: 63.9 | O23: 8 | P23: 2.2 | Q23: None | R23: Graduate | S23: Low | T23: =Table1[[#This Row],[Assignments Avg]]*0.1+Table1[[#This Row],[Midterm Score]]*0.3+Table1[[#This Row],[Final Exam Score]]*0.45+Table1[[#This Row],[Project Score]]*0.1 -> 72.955 | U23: =IF(Table1[[#This Row],[Final Score]]>=80,"A",IF(Table1[[#This Row],[Final Score]]>=70,"B",IF(Table1[[#This Row],[Final Score]]>=60,"C",IF(Table1[[#This Row],[Final Score]]>=50,"D","F")))) -> B | V23: =IF(Table1[[#This Row],[Final Score]]>=40,"Pass","Fail") -> Pass | W23: =IF(OR(Table1[[#This Row],[Attendance]]<75,Table1[[#This Row],[Final Score]]<45),"At-risk","Ok") -> At-risk | X23: =IF(Table1[[#This Row],[Study Hours]]<2,"Low Study","Normal") -> Normal
A24: S1023 | B24: Riya Singh | C24: =LEFT(Table1[[#This Row],[Name]],SEARCH(" ",Table1[[#This Row],[Name]])-1) -> Riya | D24: =RIGHT(Table1[[#This Row],[Name]],LEN(Table1[[#This Row],[Name]])-SEARCH(" ",Table1[[#This Row],[Name]])) -> Singh | E24: 18 | F24: Female | G24: 10th | H24: B | I24: 56.9 | J24: 89.5 | K24: 87.4 | L24: =Table1[[#This Row],[Final Exam Score]]-Table1[[#This Row],[Midterm Score]] -> -25.6 | M24: 61.8 | N24: 68.1 | O24: 3 | P24: 2.7 | Q24: Coding | R24: Post Graduate | S24: High | T24: =Table1[[#This Row],[Assignments Avg]]*0.1+Table1[[#This Row],[Midterm Score]]*0.3+Table1[[#This Row],[Final Exam Score]]*0.45+Table1[[#This Row],[Project Score]]*0.1 -> 69.79 | U24: =IF(Table1[[#This Row],[Final Score]]>=80,"A",IF(Table1[[#This Row],[Final Score]]>=70,"B",IF(Table1[[#This Row],[Final Score]]>=60,"C",IF(Table1[[#This Row],[Final Score]]>=50,"D","F")))) -> C | V24: =IF(Table1[[#This Row],[Final Score]]>=40,"Pass","Fail") -> Pass | W24: =IF(OR(Table1[[#This Row],[Attendance]]<75,Table1[[#This Row],[Final Score]]<45),"At-risk","Ok") -> At-risk | X24: =IF(Table1[[#This Row],[Study Hours]]<2,"Low Study","Normal") -> Normal | Y24: Row Labels | Z24: Count of Grade
A25: S1024 | B25: Yash Yadav | C25: =LEFT(Table1[[#This Row],[Name]],SEARCH(" ",Table1[[#This Row],[Name]])-1) -> Yash | D25: =RIGHT(Table1[[#This Row],[Name]],LEN(Table1[[#This Row],[Name]])-SEARCH(" ",Table1[[#This Row],[Name]])) -> Yadav | E25: 16 | F25: male | G25: 10th | H25: A | I25: 36.5 | J25: 75.1 | K25: 67.3 | L25: =Table1[[#This Row],[Final Exam Score]]-Table1[[#This Row],[Midterm Score]] -> 17.7 | M25: 85 | N25: 82.8 | O25: 5 | P25: 1.7 | Q25: Music | R25: Illiterate | S25: Medium | T25: =Table1[[#This Row],[Assignments Avg]]*0.1+Table1[[#This Row],[Midterm Score]]*0.3+Table1[[#This Row],[Final Exam Score]]*0.45+Table1[[#This Row],[Project Score]]*0.1 -> 74.23 | U25: =IF(Table1[[#This Row],[Final Score]]>=80,"A",IF(Table1[[#This Row],[Final Score]]>=70,"B",IF(Table1[[#This Row],[Final Score]]>=60,"C",IF(Table1[[#This Row],[Final Score]]>=50,"D","F")))) -> B | V25: =IF(Table1[[#This Row],[Final Score]]>=40,"Pass","Fail") -> Pass | W25: =IF(OR(Table1[[#This Row],[Attendance]]<75,Table1[[#This Row],[Final Score]]<45),"At-risk","Ok") -> At-risk | X25: =IF(Table1[[#This Row],[Study Hours]]<2,"Low Study","Normal") -> Low Study | Y25: A | Z25: 7
A26: S1025 | B26: Jyoti Deshmukh | C26: =LEFT(Table1[[#This Row],[Name]],SEARCH(" ",Table1[[#This Row],[Name]])-1) -> Jyoti | D26: =RIGHT(Table1[[#This Row],[Name]],LEN(Table1[[#This Row],[Name]])-SEARCH(" ",Table1[[#This Row],[Name]])) -> Deshmukh | E26: 15 | F26: Female | G26: 9th | H26: C | I26: 82.7 | J26: 68.9 | K26: 74.4 | L26: =Table1[[#This Row],[Final Exam Score]]-Table1[[#This Row],[Midterm Score]] -> -23.1 | M26: 51.3 | N26: 91.7 | O26: 7 | P26: 6.1 | Q26: Dance | R26: Post Graduate | S26: High | T26: =Table1[[#This Row],[Assignments Avg]]*0.1+Table1[[#This Row],[Midterm Score]]*0.3+Table1[[#This Row],[Final Exam Score]]*0.45+Table1[[#This Row],[Project Score]]*0.1 -> 61.465 | U26: =IF(Table1[[#This Row],[Final Score]]>=80,"A",IF(Table1[[#This Row],[Final Score]]>=70,"B",IF(Table1[[#This Row],[Final Score]]>=60,"C",IF(Table1[[#This Row],[Final Score]]>=50,"D","F")))) -> C | V26: =IF(Table1[[#This Row],[Final Score]]>=40,"Pass","Fail") -> Pass | W26: =IF(OR(Table1[[#This Row],[Attendance]]<75,Table1[[#This Row],[Final Score]]<45),"At-risk","Ok") -> Ok | X26: =IF(Table1[[#This Row],[Study Hours]]<2,"Low Study","Normal") -> Normal | Y26: B | Z26: 13
A27: S1026 | B27: Ankit Kadam | C27: =LEFT(Table1[[#This Row],[Name]],SEARCH(" ",Table1[[#This Row],[Name]])-1) -> Ankit | D27: =RIGHT(Table1[[#This Row],[Name]],LEN(Table1[[#This Row],[Name]])-SEARCH(" ",Table1[[#This Row],[Name]])) -> Kadam | E27: 17 | F27: Male | G27: 9th | H27: A | I27: 92.8 | J27: 36.2 | K27: 36.2 | L27: =Table1[[#This Row],[Final Exam Score]]-Table1[[#This Row],[Midterm Score]] -> 14.5 | M27: 50.7 | N27: 87.8 | O27: 9 | P27: 2.9 | Q27: Coding | R27: Post Graduate | S27: Medium | T27: =Table1[[#This Row],[Assignments Avg]]*0.1+Table1[[#This Row],[Midterm Score]]*0.3+Table1[[#This Row],[Final Exam Score]]*0.45+Table1[[#This Row],[Project Score]]*0.1 -> 46.075 | U27: =IF(Table1[[#This Row],[Final Score]]>=80,"A",IF(Table1[[#This Row],[Final Score]]>=70,"B",IF(Table1[[#This Row],[Final Score]]>=60,"C",IF(Table1[[#This Row],[Final Score]]>=50,"D","F")))) -> F | V27: =IF(Table1[[#This Row],[Final Score]]>=40,"Pass","Fail") -> Pass | W27: =IF(OR(Table1[[#This Row],[Attendance]]<75,Table1[[#This Row],[Final Score]]<45),"At-risk","Ok") -> Ok | X27: =IF(Table1[[#This Row],[Study Hours]]<2,"Low Study","Normal") -> Normal | Y27: C | Z27: 14
A28: S1027 | B28: Pallavi Pawar | C28: =LEFT(Table1[[#This Row],[Name]],SEARCH(" ",Table1[[#This Row],[Name]])-1) -> Pallavi | D28: =RIGHT(Table1[[#This Row],[Name]],LEN(Table1[[#This Row],[Name]])-SEARCH(" ",Table1[[#This Row],[Name]])) -> Pawar | E28: 15 | F28: Female | G28: 10th | H28: B | I28: 67.3 | J28: 79.9 | K28: 76.5 | L28: =Table1[[#This Row],[Final Exam Score]]-Table1[[#This Row],[Midterm Score]] -> -19.6 | M28: 56.9 | N28: 77.9 | O28: 6 | P28: 4.9 | Q28: Sports | R28: HSC | S28: Low | T28: =Table1[[#This Row],[Assignments Avg]]*0.1+Table1[[#This Row],[Midterm Score]]*0.3+Table1[[#This Row],[Final Exam Score]]*0.45+Table1[[#This Row],[Project Score]]*0.1 -> 64.335 | U28: =IF(Table1[[#This Row],[Final Score]]>=80,"A",IF(Table1[[#This Row],[Final Score]]>=70,"B",IF(Table1[[#This Row],[Final Score]]>=60,"C",IF(Table1[[#This Row],[Final Score]]>=50,"D","F")))) -> C | V28: =IF(Table1[[#This Row],[Final Score]]>=40,"Pass","Fail") -> Pass | W28: =IF(OR(Table1[[#This Row],[Attendance]]<75,Table1[[#This Row],[Final Score]]<45),"At-risk","Ok") -> At-risk | X28: =IF(Table1[[#This Row],[Study Hours]]<2,"Low Study","Normal") -> Normal | Y28: D | Z28: 12
A29: S1028 | B29: Suresh Singh | C29: =LEFT(Table1[[#This Row],[Name]],SEARCH(" ",Table1[[#This Row],[Name]])-1) -> Suresh | D29: =RIGHT(Table1[[#This Row],[Name]],LEN(Table1[[#This Row],[Name]])-SEARCH(" ",Table1[[#This Row],[Name]])) -> Singh | E29: 16 | F29: Male | G29: 10th | H29: C | I29: 52.7 | J29: 68.2 | K29: 66.3 | L29: =Table1[[#This Row],[Final Exam Score]]-Table1[[#This Row],[Midterm Score]] -> -29.8 | M29: 36.5 | N29: 51.2 | O29: 4 | P29: 2.8 | Q29: Sports | R29: Illiterate | S29: High | T29: =Table1[[#This Row],[Assignments Avg]]*0.1+Table1[[#This Row],[Midterm Score]]*0.3+Table1[[#This Row],[Final Exam Score]]*0.45+Table1[[#This Row],[Project Score]]*0.1 -> 48.255 | U29: =IF(Table1[[#This Row],[Final Score]]>=80,"A",IF(Table1[[#This Row],[Final Score]]>=70,"B",IF(Table1[[#This Row],[Final Score]]>=60,"C",IF(Table1[[#This Row],[Final Score]]>=50,"D","F")))) -> F | V29: =IF(Table1[[#This Row],[Final Score]]>=40,"Pass","Fail") -> Pass | W29: =IF(OR(Table1[[#This Row],[Attendance]]<75,Table1[[#This Row],[Final Score]]<45),"At-risk","Ok") -> At-risk | X29: =IF(Table1[[#This Row],[Study Hours]]<2,"Low Study","Normal") -> Normal | Y29: F | Z29: 4
A30: S1029 | B30: Ananya Chavan | C30: =LEFT(Table1[[#This Row],[Name]],SEARCH(" ",Table1[[#This Row],[Name]])-1) -> Ananya | D30: =RIGHT(Table1[[#This Row],[Name]],LEN(Table1[[#This Row],[Name]])-SEARCH(" ",Table1[[#This Row],[Name]])) -> Chavan | E30: 15 | F30: Female | G30: 9th | H30: A | I30: 54.3 | J30: 47 | K30: 46.8 | L30: =Table1[[#This Row],[Final Exam Score]]-Table1[[#This Row],[Midterm Score]] -> 22.1 | M30: 68.9 | N30: 91.2 | O30: 5 | P30: 3.7 | Q30: Art | R30: SSC | S30: Medium | T30: =Table1[[#This Row],[Assignments Avg]]*0.1+Table1[[#This Row],[Midterm Score]]*0.3+Table1[[#This Row],[Final Exam Score]]*0.45+Table1[[#This Row],[Project Score]]*0.1 -> 58.865 | U30: =IF(Table1[[#This Row],[Final Score]]>=80,"A",IF(Table1[[#This Row],[Final Score]]>=70,"B",IF(Table1[[#This Row],[Final Score]]>=60,"C",IF(Table1[[#This Row],[Final Score]]>=50,"D","F")))) -> D | V30: =IF(Table1[[#This Row],[Final Score]]>=40,"Pass","Fail") -> Pass | W30: =IF(OR(Table1[[#This Row],[Attendance]]<75,Table1[[#This Row],[Final Score]]<45),"At-risk","Ok") -> At-risk | X30: =IF(Table1[[#This Row],[Study Hours]]<2,"Low Study","Normal") -> Normal | Y30: Grand Total | Z30: 50
A31: S1030 | B31: Vikram Chavan | C31: =LEFT(Table1[[#This Row],[Name]],SEARCH(" ",Table1[[#This Row],[Name]])-1) -> Vikram | D31: =RIGHT(Table1[[#This Row],[Name]],LEN(Table1[[#This Row],[Name]])-SEARCH(" ",Table1[[#This Row],[Name]])) -> Chavan | E31: 16 | F31: Male | G31: 9th | H31: B | I31: 37.8 | J31: 68.9 | K31: 45.8 | L31: =Table1[[#This Row],[Final Exam Score]]-Table1[[#This Row],[Midterm Score]] -> -9.3 | M31: 36.5 | N31: 68.1 | O31: 7 | P31: 1.6 | Q31: Coding | R31: Post Graduate | S31: Low | T31: =Table1[[#This Row],[Assignments Avg]]*0.1+Table1[[#This Row],[Midterm Score]]*0.3+Table1[[#This Row],[Final Exam Score]]*0.45+Table1[[#This Row],[Project Score]]*0.1 -> 43.865 | U31: =IF(Table1[[#This Row],[Final Score]]>=80,"A",IF(Table1[[#This Row],[Final Score]]>=70,"B",IF(Table1[[#This Row],[Final Score]]>=60,"C",IF(Table1[[#This Row],[Final Score]]>=50,"D","F")))) -> F | V31: =IF(Table1[[#This Row],[Final Score]]>=40,"Pass","Fail") -> Pass | W31: =IF(OR(Table1[[#This Row],[Attendance]]<75,Table1[[#This Row],[Final Score]]<45),"At-risk","Ok") -> At-risk | X31: =IF(Table1[[#This Row],[Study Hours]]<2,"Low Study","Normal") -> Low Study
A32: S1031 | B32: Sneha Kadam | C32: =LEFT(Table1[[#This Row],[Name]],SEARCH(" ",Table1[[#This Row],[Name]])-1) -> Sneha | D32: =RIGHT(Table1[[#This Row],[Name]],LEN(Table1[[#This Row],[Name]])-SEARCH(" ",Table1[[#This Row],[Name]])) -> Kadam | E32: 15 | F32: Female | G32: 10th | H32: A | I32: 88.6 | J32: 89.5 | K32: 90 | L32: =Table1[[#This Row],[Final Exam Score]]-Table1[[#This Row],[Midterm Score]] -> -6.2 | M32: 83.8 | N32: 67 | O32: 4 | P32: 4.4 | Q32: Music | R32: SSC | S32: Low | T32: =Table1[[#This Row],[Assignments Avg]]*0.1+Table1[[#This Row],[Midterm Score]]*0.3+Table1[[#This Row],[Final Exam Score]]*0.45+Table1[[#This Row],[Project Score]]*0.1 -> 80.36 | U32: =IF(Table1[[#This Row],[Final Score]]>=80,"A",IF(Table1[[#This Row],[Final Score]]>=70,"B",IF(Table1[[#This Row],[Final Score]]>=60,"C",IF(Table1[[#This Row],[Final Score]]>=50,"D","F")))) -> A | V32: =IF(Table1[[#This Row],[Final Score]]>=40,"Pass","Fail") -> Pass | W32: =IF(OR(Table1[[#This Row],[Attendance]]<75,Table1[[#This Row],[Final Score]]<45),"At-risk","Ok") -> Ok | X32: =IF(Table1[[#This Row],[Study Hours]]<2,"Low Study","Normal") -> Normal | Y32: VLOOKUP : | Z32: =VLOOKUP("S1030",[1]!Table1[#All],17,FALSE) -> #REF!
A33: S1032 | B33: Kriti Bhosale | C33: =LEFT(Table1[[#This Row],[Name]],SEARCH(" ",Table1[[#This Row],[Name]])-1) -> Kriti | D33: =RIGHT(Table1[[#This Row],[Name]],LEN(Table1[[#This Row],[Name]])-SEARCH(" ",Table1[[#This Row],[Name]])) -> Bhosale | E33: 15 | F33: Female | G33: 10th | H33: C | I33: 75.1 | J33: 79.9 | K33: 25.2 | L33: =Table1[[#This Row],[Final Exam Score]]-Table1[[#This Row],[Midterm Score]] -> 49.9 | M33: 75.1 | N33: 52.8 | O33: 5 | P33: 2.8 | Q33: Dance | R33: SSC | S33: High | T33: =Table1[[#This Row],[Assignments Avg]]*0.1+Table1[[#This Row],[Midterm Score]]*0.3+Table1[[#This Row],[Final Exam Score]]*0.45+Table1[[#This Row],[Project Score]]*0.1 -> 54.625 | U33: =IF(Table1[[#This Row],[Final Score]]>=80,"A",IF(Table1[[#This Row],[Final Score]]>=70,"B",IF(Table1[[#This Row],[Final Score]]>=60,"C",IF(Table1[[#This Row],[Final Score]]>=50,"D","F")))) -> D | V33: =IF(Table1[[#This Row],[Final Score]]>=40,"Pass","Fail") -> Pass | W33: =IF(OR(Table1[[#This Row],[Attendance]]<75,Table1[[#This Row],[Final Score]]<45),"At-risk","Ok") -> Ok | X33: =IF(Table1[[#This Row],[Study Hours]]<2,"Low Study","Normal") -> Normal | Y33: XLOOKUP : | Z33: =_xlfn.XLOOKUP("Yash Kadam",[1]StudentData!B:B,[1]StudentData!S:S) -> 62.41
A34: S1033 | B34: Manish Kadam | C34: =LEFT(Table1[[#This Row],[Name]],SEARCH(" ",Table1[[#This Row],[Name]])-1) -> Manish | D34: =RIGHT(Table1[[#This Row],[Name]],LEN(Table1[[#This Row],[Name]])-SEARCH(" ",Table1[[#This Row],[Name]])) -> Kadam | E34: 16 | F34: Male | G34: 9th | H34: A | I34: 51.6 | J34: 25.2 | K34: 85 | L34: =Table1[[#This Row],[Final Exam Score]]-Table1[[#This Row],[Midterm Score]] -> -16.1 | M34: 68.9 | N34: 47.8 | O34: 1 | P34: 6.1 | Q34: Coding | R34: HSC | S34: Medium | T34: =Table1[[#This Row],[Assignments Avg]]*0.1+Table1[[#This Row],[Midterm Score]]*0.3+Table1[[#This Row],[Final Exam Score]]*0.45+Table1[[#This Row],[Project Score]]*0.1 -> 63.805 | U34: =IF(Table1[[#This Row],[Final Score]]>=80,"A",IF(Table1[[#This Row],[Final Score]]>=70,"B",IF(Table1[[#This Row],[Final Score]]>=60,"C",IF(Table1[[#This Row],[Final Score]]>=50,"D","F")))) -> C | V34: =IF(Table1[[#This Row],[Final Score]]>=40,"Pass","Fail") -> Pass | W34: =IF(OR(Table1[[#This Row],[Attendance]]<75,Table1[[#This Row],[Final Score]]<45),"At-risk","Ok") -> At-risk | X34: =IF(Table1[[#This Row],[Study Hours]]<2,"Low Study","Normal") -> Normal
A35: S1034 | B35: Isha Naik | C35: =LEFT(Table1[[#This Row],[Name]],SEARCH(" ",Table1[[#This Row],[Name]])-1) -> Isha | D35: =RIGHT(Table1[[#This Row],[Name]],LEN(Table1[[#This Row],[Name]])-SEARCH(" ",Table1[[#This Row],[Name]])) -> Naik | E35: 16 | F35: Female | G35: 9th | H35: B | I35: 76 | J35: 83.8 | K35: 92.2 | L35: =Table1[[#This Row],[Final Exam Score]]-Table1[[#This Row],[Midterm Score]] -> 0 | M35: 92.2 | N35: 47.7 | O35: 9 | P35: 3 | Q35: Sports | R35: Graduate | S35: High | T35: =Table1[[#This Row],[Assignments Avg]]*0.1+Table1[[#This Row],[Midterm Score]]*0.3+Table1[[#This Row],[Final Exam Score]]*0.45+Table1[[#This Row],[Project Score]]*0.1 -> 82.3 | U35: =IF(Table1[[#This Row],[Final Score]]>=80,"A",IF(Table1[[#This Row],[Final Score]]>=70,"B",IF(Table1[[#This Row],[Final Score]]>=60,"C",IF(Table1[[#This Row],[Final Score]]>=50,"D","F")))) -> A | V35: =IF(Table1[[#This Row],[Final Score]]>=40,"Pass","Fail") -> Pass | W35: =IF(OR(Table1[[#This Row],[Attendance]]<75,Table1[[#This Row],[Final Score]]<45),"At-risk","Ok") -> Ok | X35: =IF(Table1[[#This Row],[Study Hours]]<2,"Low Study","Normal") -> Normal
A36: S1035 | B36: Tanvi Thakur | C36: =LEFT(Table1[[#This Row],[Name]],SEARCH(" ",Table1[[#This Row],[Name]])-1) -> Tanvi | D36: =RIGHT(Table1[[#This Row],[Name]],LEN(Table1[[#This Row],[Name]])-SEARCH(" ",Table1[[#This Row],[Name]])) -> Thakur | E36: 15 | F36: Female | G36: 10th | H36: C | I36: 58.4 | J36: 86.7 | K36: 76.6 | L36: =Table1[[#This Row],[Final Exam Score]]-Table1[[#This Row],[Midterm Score]] -> 7.2 | M36: 83.8 | N36: 69.6 | O36: 3 | P36: 1.7 | Q36: None | R36: Post Graduate | S36: Medium | T36: =Table1[[#This Row],[Assignments Avg]]*0.1+Table1[[#This Row],[Midterm Score]]*0.3+Table1[[#This Row],[Final Exam Score]]*0.45+Table1[[#This Row],[Project Score]]*0.1 -> 76.32 | U36: =IF(Table1[[#This Row],[Final Score]]>=80,"A",IF(Table1[[#This Row],[Final Score]]>=70,"B",IF(Table1[[#This Row],[Final Score]]>=60,"C",IF(Table1[[#This Row],[Final Score]]>=50,"D","F")))) -> B | V36: =IF(Table1[[#This Row],[Final Score]]>=40,"Pass","Fail") -> Pass | W36: =IF(OR(Table1[[#This Row],[Attendance]]<75,Table1[[#This Row],[Final Score]]<45),"At-risk","Ok") -> At-risk | X36: =IF(Table1[[#This Row],[Study Hours]]<2,"Low Study","Normal") -> Low Study
A37: S1036 | B37: Deepak Bhosale | C37: =LEFT(Table1[[#This Row],[Name]],SEARCH(" ",Table1[[#This Row],[Name]])-1) -> Deepak | D37: =RIGHT(Table1[[#This Row],[Name]],LEN(Table1[[#This Row],[Name]])-SEARCH(" ",Table1[[#This Row],[Name]])) -> Bhosale | E37: 16 | F37: Male | G37: 10th | H37: A | I37: 93.8 | J37: 50.7 | K37: 76.5 | L37: =Table1[[#This Row],[Final Exam Score]]-Table1[[#This Row],[Midterm Score]] -> 7.3 | M37: 83.8 | N37: 82.3 | O37: 2 | P37: 4.9 | Q37: Art | R37: Illiterate | S37: Low | T37: =Table1[[#This Row],[Assignments Avg]]*0.1+Table1[[#This Row],[Midterm Score]]*0.3+Table1[[#This Row],[Final Exam Score]]*0.45+Table1[[#This Row],[Project Score]]*0.1 -> 73.96 | U37: =IF(Table1[[#This Row],[Final Score]]>=80,"A",IF(Table1[[#This Row],[Final Score]]>=70,"B",IF(Table1[[#This Row],[Final Score]]>=60,"C",IF(Table1[[#This Row],[Final Score]]>=50,"D","F")))) -> B | V37: =IF(Table1[[#This Row],[Final Score]]>=40,"Pass","Fail") -> Pass | W37: =IF(OR(Table1[[#This Row],[Attendance]]<75,Table1[[#This Row],[Final Score]]<45),"At-risk","Ok") -> Ok | X37: =IF(Table1[[#This Row],[Study Hours]]<2,"Low Study","Normal") -> Normal
A38: S1037 | B38: Harsh Pawar | C38: =LEFT(Table1[[#This Row],[Name]],SEARCH(" ",Table1[[#This Row],[Name]])-1) -> Harsh | D38: =RIGHT(Table1[[#This Row],[Name]],LEN(Table1[[#This Row],[Name]])-SEARCH(" ",Table1[[#This Row],[Name]])) -> Pawar | E38: 15 | F38: Male | G38: 9th | H38: B | I38: 55.3 | J38: 44.5 | K38: 87.4 | L38: =Table1[[#This Row],[Final Exam Score]]-Table1[[#This Row],[Midterm Score]] -> -7.5 | M38: 79.9 | N38: 77.7 | O38: 7 | P38: 1.4 | Q38: Coding | R38: Post Graduate | S38: High | T38: =Table1[[#This Row],[Assignments Avg]]*0.1+Table1[[#This Row],[Midterm Score]]*0.3+Table1[[#This Row],[Final Exam Score]]*0.45+Table1[[#This Row],[Project Score]]*0.1 -> 74.395 | U38: =IF(Table1[[#This Row],[Final Score]]>=80,"A",IF(Table1[[#This Row],[Final Score]]>=70,"B",IF(Table1[[#This Row],[Final Score]]>=60,"C",IF(Table1[[#This Row],[Final Score]]>=50,"D","F")))) -> B | V38: =IF(Table1[[#This Row],[Final Score]]>=40,"Pass","Fail") -> Pass | W38: =IF(OR(Table1[[#This Row],[Attendance]]<75,Table1[[#This Row],[Final Score]]<45),"At-risk","Ok") -> At-risk | X38: =IF(Table1[[#This Row],[Study Hours]]<2,"Low Study","Normal") -> Low Study
A39: S1038 | B39: Aryan Jadhav | C39: =LEFT(Table1[[#This Row],[Name]],SEARCH(" ",Table1[[#This Row],[Name]])-1) -> Aryan | D39: =RIGHT(Table1[[#This Row],[Name]],LEN(Table1[[#This Row],[Name]])-SEARCH(" ",Table1[[#This Row],[Name]])) -> Jadhav | E39: 16 | F39: male | G39: 9th | H39: A | I39: 47 | J39: 68.9 | K39: 85.2 | L39: =Table1[[#This Row],[Final Exam Score]]-Table1[[#This Row],[Midterm Score]] -> -16.3 | M39: 68.9 | N39: 44.5 | O39: 3 | P39: 7.6 | Q39: Music | R39: Post Graduate | S39: Medium | T39: =Table1[[#This Row],[Assignments Avg]]*0.1+Table1[[#This Row],[Midterm Score]]*0.3+Table1[[#This Row],[Final Exam Score]]*0.45+Table1[[#This Row],[Project Score]]*0.1 -> 67.905 | U39: =IF(Table1[[#This Row],[Final Score]]>=80,"A",IF(Table1[[#This Row],[Final Score]]>=70,"B",IF(Table1[[#This Row],[Final Score]]>=60,"C",IF(Table1[[#This Row],[Final Score]]>=50,"D","F")))) -> C | V39: =IF(Table1[[#This Row],[Final Score]]>=40,"Pass","Fail") -> Pass | W39: =IF(OR(Table1[[#This Row],[Attendance]]<75,Table1[[#This Row],[Final Score]]<45),"At-risk","Ok") -> At-risk | X39: =IF(Table1[[#This Row],[Study Hours]]<2,"Low Study","Normal") -> Normal
A40: S1039 | B40: Yash Kadam | C40: =LEFT(Table1[[#This Row],[Name]],SEARCH(" ",Table1[[#This Row],[Name]])-1) -> Yash | D40: =RIGHT(Table1[[#This Row],[Name]],LEN(Table1[[#This Row],[Name]])-SEARCH(" ",Table1[[#This Row],[Name]])) -> Kadam | E40: 16 | F40: Male | G40: 10th | H40: C | I40: 36.5 | J40: 36.5 | K40: 76.5 | L40: =Table1[[#This Row],[Final Exam Score]]-Table1[[#This Row],[Midterm Score]] -> -8.3 | M40: 68.2 | N40: 51.2 | O40: 5 | P40: 6.6 | Q40: Dance | R40: HSC | S40: Low | T40: =Table1[[#This Row],[Assignments Avg]]*0.1+Table1[[#This Row],[Midterm Score]]*0.3+Table1[[#This Row],[Final Exam Score]]*0.45+Table1[[#This Row],[Project Score]]*0.1 -> 62.41 | U40: =IF(Table1[[#This Row],[Final Score]]>=80,"A",IF(Table1[[#This Row],[Final Score]]>=70,"B",IF(Table1[[#This Row],[Final Score]]>=60,"C",IF(Table1[[#This Row],[Final Score]]>=50,"D","F")))) -> C | V40: =IF(Table1[[#This Row],[Final Score]]>=40,"Pass","Fail") -> Pass | W40: =IF(OR(Table1[[#This Row],[Attendance]]<75,Table1[[#This Row],[Final Score]]<45),"At-risk","Ok") -> At-risk | X40: =IF(Table1[[#This Row],[Study Hours]]<2,"Low Study","Normal") -> Normal
...

Sheet Dashboard
A18: Overall Average Score: | B18: =AVERAGE(StudentData!T2:T51) -> 66.0418
A19: Total At-Risk Students: | B19: =COUNTIF(StudentData!W2:W51,"At-Risk") -> 26
A21: Top 5 Performers | B21: =LARGE(StudentData!T:T,1) -> 85.925
B22: =LARGE(StudentData!T:T,2) -> 85.925
B23: =LARGE(StudentData!T:T,3) -> 83.3
B24: =LARGE(StudentData!T:T,4) -> 82.3
B25: =LARGE(StudentData!T:T,5) -> 81.245
